Internal Server Error: /temp
Traceback (most recent call last):
  File "C:\Users\abx\AppData\Local\Programs\Python\Python36-32\lib\site-packages\django-2.1b1-py3.6.egg\django\core\handlers\exception.py", line 34, in inner
    response = get_response(request)
  File "C:\Users\abx\AppData\Local\Programs\Python\Python36-32\lib\site-packages\django-2.1b1-py3.6.egg\django\core\handlers\base.py", line 137, in _get_response
    "returned None instead." % (callback.__module__, view_name)
ValueError: The view home.views.temp didn't return an HttpResponse object. It returned None instead.
"GET /temp HTTP/1.1" 500 58214
ERROR:home.views:It is Test Error For Logging modeule
DEBUG:django.db.backends:(0.000) SELECT "django_session"."session_key", "django_session"."session_data", "django_session"."expire_date" FROM "django_session" WHERE ("django_session"."expire_date" > '2019-02-25 15:18:33.455025' AND "django_session"."session_key" = '46j2zwb03t1k00wh6oe7qau3bc3fsyr8'); args=('2019-02-25 15:18:33.455025', '46j2zwb03t1k00wh6oe7qau3bc3fsyr8')
DEBUG:django.db.backends:(0.000) SELECT "auth_user"."id", "auth_user"."password", "auth_user"."last_login", "auth_user"."is_superuser", "auth_user"."username", "auth_user"."first_name", "auth_user"."last_name", "auth_user"."email", "auth_user"."is_staff", "auth_user"."is_active", "auth_user"."date_joined" FROM "auth_user" WHERE "auth_user"."id" = 19; args=(19,)
Internal Server Error: /temp
Traceback (most recent call last):
  File "C:\Users\abx\AppData\Local\Programs\Python\Python36-32\lib\site-packages\django-2.1b1-py3.6.egg\django\core\handlers\exception.py", line 34, in inner
    response = get_response(request)
  File "C:\Users\abx\AppData\Local\Programs\Python\Python36-32\lib\site-packages\django-2.1b1-py3.6.egg\django\core\handlers\base.py", line 137, in _get_response
    "returned None instead." % (callback.__module__, view_name)
ValueError: The view home.views.temp didn't return an HttpResponse object. It returned None instead.
ERROR:django.request:Internal Server Error: /temp
Traceback (most recent call last):
  File "C:\Users\abx\AppData\Local\Programs\Python\Python36-32\lib\site-packages\django-2.1b1-py3.6.egg\django\core\handlers\exception.py", line 34, in inner
    response = get_response(request)
  File "C:\Users\abx\AppData\Local\Programs\Python\Python36-32\lib\site-packages\django-2.1b1-py3.6.egg\django\core\handlers\base.py", line 137, in _get_response
    "returned None instead." % (callback.__module__, view_name)
ValueError: The view home.views.temp didn't return an HttpResponse object. It returned None instead.
"GET /temp HTTP/1.1" 500 58214
ERROR:django.server:"GET /temp HTTP/1.1" 500 58214
ERROR:home.views:It is Test Error For Logging modeule
DEBUG:django.db.backends:(0.001) SELECT "django_session"."session_key", "django_session"."session_data", "django_session"."expire_date" FROM "django_session" WHERE ("django_session"."expire_date" > '2019-02-25 15:18:36.576958' AND "django_session"."session_key" = '46j2zwb03t1k00wh6oe7qau3bc3fsyr8'); args=('2019-02-25 15:18:36.576958', '46j2zwb03t1k00wh6oe7qau3bc3fsyr8')
DEBUG:django.db.backends:(0.000) SELECT "auth_user"."id", "auth_user"."password", "auth_user"."last_login", "auth_user"."is_superuser", "auth_user"."username", "auth_user"."first_name", "auth_user"."last_name", "auth_user"."email", "auth_user"."is_staff", "auth_user"."is_active", "auth_user"."date_joined" FROM "auth_user" WHERE "auth_user"."id" = 19; args=(19,)
Internal Server Error: /temp
Traceback (most recent call last):
  File "C:\Users\abx\AppData\Local\Programs\Python\Python36-32\lib\site-packages\django-2.1b1-py3.6.egg\django\core\handlers\exception.py", line 34, in inner
    response = get_response(request)
  File "C:\Users\abx\AppData\Local\Programs\Python\Python36-32\lib\site-packages\django-2.1b1-py3.6.egg\django\core\handlers\base.py", line 137, in _get_response
    "returned None instead." % (callback.__module__, view_name)
ValueError: The view home.views.temp didn't return an HttpResponse object. It returned None instead.
ERROR:django.request:Internal Server Error: /temp
Traceback (most recent call last):
  File "C:\Users\abx\AppData\Local\Programs\Python\Python36-32\lib\site-packages\django-2.1b1-py3.6.egg\django\core\handlers\exception.py", line 34, in inner
    response = get_response(request)
  File "C:\Users\abx\AppData\Local\Programs\Python\Python36-32\lib\site-packages\django-2.1b1-py3.6.egg\django\core\handlers\base.py", line 137, in _get_response
    "returned None instead." % (callback.__module__, view_name)
ValueError: The view home.views.temp didn't return an HttpResponse object. It returned None instead.
"GET /temp HTTP/1.1" 500 58215
ERROR:django.server:"GET /temp HTTP/1.1" 500 58215
ERROR:home.views:It is Test Error For Logging modeule
DEBUG:django.db.backends:(0.001) SELECT "django_session"."session_key", "django_session"."session_data", "django_session"."expire_date" FROM "django_session" WHERE ("django_session"."expire_date" > '2019-02-25 15:18:52.942573' AND "django_session"."session_key" = '46j2zwb03t1k00wh6oe7qau3bc3fsyr8'); args=('2019-02-25 15:18:52.942573', '46j2zwb03t1k00wh6oe7qau3bc3fsyr8')
DEBUG:django.db.backends:(0.000) SELECT "auth_user"."id", "auth_user"."password", "auth_user"."last_login", "auth_user"."is_superuser", "auth_user"."username", "auth_user"."first_name", "auth_user"."last_name", "auth_user"."email", "auth_user"."is_staff", "auth_user"."is_active", "auth_user"."date_joined" FROM "auth_user" WHERE "auth_user"."id" = 19; args=(19,)
Internal Server Error: /temp
Traceback (most recent call last):
  File "C:\Users\abx\AppData\Local\Programs\Python\Python36-32\lib\site-packages\django-2.1b1-py3.6.egg\django\core\handlers\exception.py", line 34, in inner
    response = get_response(request)
  File "C:\Users\abx\AppData\Local\Programs\Python\Python36-32\lib\site-packages\django-2.1b1-py3.6.egg\django\core\handlers\base.py", line 137, in _get_response
    "returned None instead." % (callback.__module__, view_name)
ValueError: The view home.views.temp didn't return an HttpResponse object. It returned None instead.
ERROR:django.request:Internal Server Error: /temp
Traceback (most recent call last):
  File "C:\Users\abx\AppData\Local\Programs\Python\Python36-32\lib\site-packages\django-2.1b1-py3.6.egg\django\core\handlers\exception.py", line 34, in inner
    response = get_response(request)
  File "C:\Users\abx\AppData\Local\Programs\Python\Python36-32\lib\site-packages\django-2.1b1-py3.6.egg\django\core\handlers\base.py", line 137, in _get_response
    "returned None instead." % (callback.__module__, view_name)
ValueError: The view home.views.temp didn't return an HttpResponse object. It returned None instead.
"GET /temp HTTP/1.1" 500 58214
ERROR:django.server:"GET /temp HTTP/1.1" 500 58214
ERROR:home.views:It is Test Error For Logging modeule
DEBUG:django.db.backends:(0.001) SELECT "django_session"."session_key", "django_session"."session_data", "django_session"."expire_date" FROM "django_session" WHERE ("django_session"."expire_date" > '2019-02-25 15:19:02.163508' AND "django_session"."session_key" = '46j2zwb03t1k00wh6oe7qau3bc3fsyr8'); args=('2019-02-25 15:19:02.163508', '46j2zwb03t1k00wh6oe7qau3bc3fsyr8')
DEBUG:django.db.backends:(0.000) SELECT "auth_user"."id", "auth_user"."password", "auth_user"."last_login", "auth_user"."is_superuser", "auth_user"."username", "auth_user"."first_name", "auth_user"."last_name", "auth_user"."email", "auth_user"."is_staff", "auth_user"."is_active", "auth_user"."date_joined" FROM "auth_user" WHERE "auth_user"."id" = 19; args=(19,)
Internal Server Error: /temp
Traceback (most recent call last):
  File "C:\Users\abx\AppData\Local\Programs\Python\Python36-32\lib\site-packages\django-2.1b1-py3.6.egg\django\core\handlers\exception.py", line 34, in inner
    response = get_response(request)
  File "C:\Users\abx\AppData\Local\Programs\Python\Python36-32\lib\site-packages\django-2.1b1-py3.6.egg\django\core\handlers\base.py", line 137, in _get_response
    "returned None instead." % (callback.__module__, view_name)
ValueError: The view home.views.temp didn't return an HttpResponse object. It returned None instead.
ERROR:django.request:Internal Server Error: /temp
Traceback (most recent call last):
  File "C:\Users\abx\AppData\Local\Programs\Python\Python36-32\lib\site-packages\django-2.1b1-py3.6.egg\django\core\handlers\exception.py", line 34, in inner
    response = get_response(request)
  File "C:\Users\abx\AppData\Local\Programs\Python\Python36-32\lib\site-packages\django-2.1b1-py3.6.egg\django\core\handlers\base.py", line 137, in _get_response
    "returned None instead." % (callback.__module__, view_name)
ValueError: The view home.views.temp didn't return an HttpResponse object. It returned None instead.
"GET /temp HTTP/1.1" 500 58214
ERROR:django.server:"GET /temp HTTP/1.1" 500 58214
